Using Traceback (most recent call last):
 cuda:0
  File "/home/dewe/.local/lib/python3.6/site-packages/gym/envs/registration.py", line 121, in spec
    return self.env_specs[id]
KeyError: 'BaxterGym-v0'

During handling of the above exception, another exception occurred:

Traceback (most recent call last):
  File "/home/dewe/ros_ws/src/drl_project/scripts/test.py", line 118, in <module>
    env = gym.make(args.env)
  File "/home/dewe/.local/lib/python3.6/site-packages/gym/envs/registration.py", line 145, in make
    return registry.make(id, **kwargs)
  File "/home/dewe/.local/lib/python3.6/site-packages/gym/envs/registration.py", line 89, in make
    spec = self.spec(path)
  File "/home/dewe/.local/lib/python3.6/site-packages/gym/envs/registration.py", line 131, in spec
    raise error.UnregisteredEnv('No registered env with id: {}'.format(id))
gym.error.UnregisteredEnv: No registered env with id: BaxterGym-v0
